Workbook

Sheet Master Data
A1: India National Power Portal — Monthly Coal Report | Master Dataset | April 2023 – January 2026 | Quantities in '000 Tonnes
A2: IDENTIFICATION | E2: CAPACITY | F2: COAL RECEIPTS ('000 Tonnes) | L2: OFFTAKE ('000 Tonnes) | N2: STOCK POSITION
A3: Period | B3: Region | C3: Plant / TPS Name | D3: State | E3: Installed MW | F3: CIL | G3: SCCL | H3: Captive Mines | I3: E-Auction | J3: Import | K3: Others | L3: Total Receipt | M3: Total Consumption | N3: Closing Stocks | O3: Stock Cover (Days)
A4: April 2023 | B4: Eastern | C4: BAKRESWAR TPS | D4: =VLOOKUP(C4,'State Key'!$A$2:$B$210,2,False) -> West Bengal | E4: 1050 | F4: 3.6555 | G4: 0 | H4: 384.404 | I4: 0 | J4: 0 | K4: 0 | L4: 388.0595 | M4: 406.608 | N4: 88.44 | O4: 6.5 | P4: =SUM(F4:K4) -> 388.0595
A5: April 2023 | B5: Eastern | C5: BANDEL TPS | D5: =VLOOKUP(C5,'State Key'!$A$2:$B$210,2,False) -> West Bengal | E5: 270 | F5: 7.938 | G5: 0 | H5: 104.837 | I5: 0 | J5: 0 | K5: 0 | L5: 112.775 | M5: 113.598 | N5: 21.16 | O5: 5.6 | P5: =SUM(F5:K5) -> 112.775
A6: April 2023 | B6: Eastern | C6: BARAUNI TPS | D6: =VLOOKUP(C6,'State Key'!$A$2:$B$210,2,False) -> Bihar | E6: 710 | F6: 3.72 | G6: 0 | H6: 249.46 | I6: 0 | J6: 0 | K6: 0 | L6: 253.18 | M6: 236.258 | N6: 73.143 | O6: 9.3 | P6: =SUM(F6:K6) -> 253.18
A7: April 2023 | B7: Eastern | C7: BARH STPS | D7: =VLOOKUP(C7,'State Key'!$A$2:$B$210,2,False) -> Bihar | E7: 2640 | F7: 521.02 | G7: 0 | H7: 64.67 | I7: 15.905 | J7: 0 | K7: 0 | L7: 601.595 | M7: 791.713 | N7: 249.5 | O7: 9.5 | P7: =SUM(F7:K7) -> 601.595
A8: April 2023 | B8: Eastern | C8: BOKARO TPS `A` EXP | D8: =VLOOKUP(C8,'State Key'!$A$2:$B$210,2,False) -> Jharkhand | E8: 500 | F8: 202.264 | G8: 0 | H8: 0 | I8: 0 | J8: 0 | K8: 0 | L8: 202.264 | M8: 198.583 | N8: 152.13 | O8: 23 | P8: =SUM(F8:K8) -> 202.264
A9: April 2023 | B9: Eastern | C9: BUDGE BUDGE TPS | D9: =VLOOKUP(C9,'State Key'!$A$2:$B$210,2,False) -> West Bengal | E9: 750 | F9: 86.746 | G9: 0 | H9: 157.708 | I9: 0 | J9: 0 | K9: 93.864 | L9: 338.318 | M9: 302.961 | N9: 351.57 | O9: 34.8 | P9: =SUM(F9:K9) -> 338.318
A10: April 2023 | B10: Eastern | C10: CHANDRAPURA(DVC) TPS | D10: =VLOOKUP(C10,'State Key'!$A$2:$B$210,2,False) -> Jharkhand | E10: 500 | F10: 72.808 | G10: 0 | H10: 0 | I10: 0 | J10: 0 | K10: 0 | L10: 72.808 | M10: 114.099 | N10: 179.61 | O10: 47.2 | P10: =SUM(F10:K10) -> 72.808
A11: April 2023 | B11: Eastern | C11: D.P.L. TPS | D11: =VLOOKUP(C11,'State Key'!$A$2:$B$210,2,False) -> West Bengal | E11: 550 | F11: 112.88 | G11: 0 | H11: 91.353 | I11: 0 | J11: 0 | K11: 0 | L11: 204.233 | M11: 184.06 | N11: 25.44 | O11: 4.1 | P11: =SUM(F11:K11) -> 204.233
A12: April 2023 | B12: Eastern | C12: DARLIPALI STPS | D12: =VLOOKUP(C12,'State Key'!$A$2:$B$210,2,False) -> Odisha | E12: 1600 | F12: 0.12 | G12: 0 | H12: 863.46 | I12: 0 | J12: 0 | K12: 0 | L12: 863.58 | M12: 777.588 | N12: 456.5 | O12: 17.6 | P12: =SUM(F12:K12) -> 863.58
A13: April 2023 | B13: Eastern | C13: DERANG TPP | D13: =VLOOKUP(C13,'State Key'!$A$2:$B$210,2,False) -> Odisha | E13: 1200 | F13: 347.621 | G13: 0 | H13: 0 | I13: 0 | J13: 0 | K13: 141.197 | L13: 488.818 | M13: 407.18 | N13: 599.16 | O13: 44.1 | P13: =SUM(F13:K13) -> 488.818
A14: April 2023 | B14: Eastern | C14: DISHERGARH TPP | D14: =VLOOKUP(C14,'State Key'!$A$2:$B$210,2,False) -> West Bengal | E14: 12 | F14: 6.43 | G14: 0 | H14: 0 | I14: 0 | J14: 0 | K14: 0 | L14: 6.43 | M14: 6.56 | N14: 4.43 | O14: 20.3 | P14: =SUM(F14:K14) -> 6.43
A15: April 2023 | B15: Eastern | C15: DURGAPUR STEEL TPS | D15: =VLOOKUP(C15,'State Key'!$A$2:$B$210,2,False) -> West Bengal | E15: 1000 | F15: 377.184 | G15: 4.096 | H15: 0 | I15: 32.394 | J15: 0 | K15: 0 | L15: 413.674 | M15: 402.126 | N15: 105.1 | O15: 7.8 | P15: =SUM(F15:K15) -> 413.674
... A37: April 2023 | B37: Eastern | C37: TENUGHAT TPS | D37: =VLOOKUP(C37,'State Key'!$A$2:$B$210,2,False) -> Jharkhand | E37: 420 | F37: 121.35 | G37: 0 | H37: 0 | I37: 0 | J37: 0 | K37: 0 | L37: 121.35 | M37: 154.52 | N37: 126.39 | O37: 24.5 | P37: =SUM(F37:K37) -> 121.35
A38: April 2023 | B38: Eastern | C38: TITAGARH TPS | D38: =VLOOKUP(C38,'State Key'!$A$2:$B$210,2,False) -> West Bengal | E38: 240 | F38: 0 | G38: 0 | H38: 0 | I38: 0 | J38: 0 | K38: 0 | L38: 0 | M38: 0 | N38: 0.67 | O38: — | P38: =SUM(F38:K38) -> 0
A39: April 2023 | B39: Eastern | C39: UTKAL TPP (IND BARATH) | D39: =VLOOKUP(C39,'State Key'!$A$2:$B$210,2,False) -> Odisha | E39: 350 | F39: 0 | G39: 0 | H39: 0 | I39: 0 | J39: 0 | K39: 0 | L39: 0 | M39: 0 | N39: 0 | O39: — | P39: =SUM(F39:K39) -> 0
A40: April 2023 | B40: Eastern | C40: VEDANTA TPP | D40: =VLOOKUP(C40,'State Key'!$A$2:$B$210,2,False) -> Odisha | E40: 600 | F40: 170.24 | G40: 0 | H40: 0 | I40: 0 | J40: 0 | K40: 0 | L40: 170.24 | M40: 160.77 | N40: 148.23 | O40: 27.7 | P40: =SUM(F40:K40) -> 170.24
A41: April 2023 | B41: Northern | C41: ANPARA C TPS | D41: =VLOOKUP(C41,'State Key'!$A$2:$B$210,2,False) -> Uttar Pradesh | E41: 1200 | F41: 494.745 | G41: 0 | H41: 0 | I41: 0 | J41: 0 | K41: 0 | L41: 494.745 | M41: 490.0869 | N41: 93.16 | O41: 5.7 | P41: =SUM(F41:K41) -> 494.745
A42: April 2023 | B42: Northern | C42: ANPARA TPS | D42: =VLOOKUP(C42,'State Key'!$A$2:$B$210,2,False) -> Uttar Pradesh | E42: 2630 | F42: 817.05 | G42: 0 | H42: 0 | I42: 0 | J42: 0 | K42: 0 | L42: 817.05 | M42: 821.152 | N42: 925.93 | O42: 33.8 | P42: =SUM(F42:K42) -> 817.05
A43: April 2023 | B43: Northern | C43: BARKHERA TPS | D43: =VLOOKUP(C43,'State Key'!$A$2:$B$210,2,False) -> Uttar Pradesh | E43: 90 | F43: 34.91 | G43: 0 | H43: 0 | I43: 0 | J43: 0 | K43: 0 | L43: 34.91 | M43: 16.01 | N43: 61.22 | O43: 114.7 | P43: =SUM(F43:K43) -> 34.91
A44: April 2023 | B44: Northern | C44: CHHABRA-I PH-1 TPP | D44: =VLOOKUP(C44,'State Key'!$A$2:$B$210,2,False) -> Rajasthan | E44: 500 | F44: 127.0453 | G44: 0 | H44: 0 | I44: 0 | J44: 0 | K44: 0 | L44: 127.0453 | M44: 163.594 | N44: 29.66 | O44: 5.4 | P44: =SUM(F44:K44) -> 127.0453
A45: April 2023 | B45: Northern | C45: CHHABRA-I PH-2 TPP | D45: =VLOOKUP(C45,'State Key'!$A$2:$B$210,2,False) -> Rajasthan | E45: 500 | F45: 0.0582 | G45: 0 | H45: 182.9332 | I45: 0 | J45: 0 | K45: 0 | L45: 182.9914 | M45: 143.7478 | N45: 133.44 | O45: 27.8 | P45: =SUM(F45:K45) -> 182.9914
A46: April 2023 | B46: Northern | C46: CHHABRA-II TPP | D46: =VLOOKUP(C46,'State Key'!$A$2:$B$210,2,False) -> Rajasthan | E46: 1320 | F46: 76.60254 | G46: 0 | H46: 301.93574 | I46: 0 | J46: 0 | K46: 0 | L46: 378.53828 | M46: 405.276 | N46: 79.31 | O46: 5.9 | P46: =SUM(F46:K46) -> 378.53828
A47: April 2023 | B47: Northern | C47: DADRI (NCTPP) | D47: =VLOOKUP(C47,'State Key'!$A$2:$B$210,2,False) -> Uttar Pradesh | E47: 1820 | F47: 479.3 | G47: 0 | H47: 78.08 | I47: 84.65 | J47: 0 | K47: 0 | L47: 642.03 | M47: 616.552 | N47: 271.934 | O47: 13.2 | P47: =SUM(F47:K47) -> 642.03
A48: April 2023 | B48: Northern | C48: GH TPS (LEH.MOH.) | D48: =VLOOKUP(C48,'State Key'!$A$2:$B$210,2,False) -> Punjab | E48: 920 | F48: 203.333 | G48: 0 | H48: 146.442 | I48: 0 | J48: 0 | K48: 0 | L48: 349.775 | M48: 204.548 | N48: 398.016 | O48: 58.4 | P48: =SUM(F48:K48) -> 349.775
A49: April 2023 | B49: Northern | C49: GOINDWAL SAHIB TPP | D49: =VLOOKUP(C49,'State Key'!$A$2:$B$210,2,False) -> Punjab | E49: 540 | F49: 139.017 | G49: 0 | H49: 0 | I49: 0 | J49: 0 | K49: 0 | L49: 139.017 | M49: 132.581 | N49: 64.82 | O49: 14.7 | P49: =SUM(F49:K49) -> 139.017
A50: April 2023 | B50: Northern | C50: HARDUAGANJ TPS | D50: =VLOOKUP(C50,'State Key'!$A$2:$B$210,2,False) -> Uttar Pradesh | E50: 1265 | F50: 241.017 | G50: 0 | H50: 0 | I50: 0 | J50: 0 | K50: 0 | L50: 241.017 | M50: 333.9604 | N50: 225.48 | O50: 20.3 | P50: =SUM(F50:K50) -> 241.017
A51: April 2023 | B51: Northern | C51: INDIRA GANDHI STPP | D51: =VLOOKUP(C51,'State Key'!$A$2:$B$210,2,False) -> Haryana | E51: 1500 | F51: 489.444 | G51: 12.145 | H51: 0 | I51: 0 | J51: 0 | K51: 0 | L51: 501.589 | M51: 480.948 | N51: 255.99 | O51: 16 | P51: =SUM(F51:K51) -> 501.589
... A100: April 2023 | B100: Southern | C100: SINGARENI TPP | D100: =VLOOKUP(C100,'State Key'!$A$2:$B$210,2,False) -> Telangana | E100: 1200 | F100: 0 | G100: 463.887 | H100: 0 | I100: 0 | J100: 0 | K100: 0 | L100: 463.887 | M100: 500.17 | N100: 90.42 | O100: 5.4 | P100: =SUM(F100:K100) -> 463.887
A101: April 2023 | B101: Southern | C101: THAMMINAPATNAM TPS | D101: =VLOOKUP(C101,'State Key'!$A$2:$B$210,2,False) -> Andhra Pradesh | E101: 300 | F101: 0 | G101: 0 | H101: 0 | I101: 0 | J101: 0 | K101: 0 | L101: 0 | M101: 0 | N101: 0.98 | O101: — | P101: =SUM(F101:K101) -> 0
A102: April 2023 | B102: Southern | C102: TORANGALLU TPS(SBU-I) | D102: =VLOOKUP(C102,'State Key'!$A$2:$B$210,2,False) -> Karnataka | E102: 260 | F102: 0 | G102: 0 | H102: 0 | I102: 50.07 | J102: 0 | K102: 0 | L102: 50.07 | M102: 50.0698 | N102: 0 | O102: 0 | P102: =SUM(F102:K102) -> 50.07
A103: April 2023 | B103: Southern | C103: TORANGALLU TPS(SBU-II) | D103: =VLOOKUP(C103,'State Key'!$A$2:$B$210,2,False) -> Karnataka | E103: 600 | F103: 0 | G103: 0 | H103: 0 | I103: 67.11 | J103: 0 | K103: 0 | L103: 67.11 | M103: 90.26 | N103: 14.5 | O103: 4.8 | P103: =SUM(F103:K103) -> 67.11
A104: April 2023 | B104: Southern | C104: TUTICORIN (P) TPP | D104: =VLOOKUP(C104,'State Key'!$A$2:$B$210,2,False) -> Tamil Nadu | E104: 300 | F104: 0 | G104: 0 | H104: 0 | I104: 0 | J104: 0 | K104: 0 | L104: 0 | M104: 0 | N104: 0 | O104: — | P104: =SUM(F104:K104) -> 0
A105: April 2023 | B105: Southern | C105: TUTICORIN TPP ST-IV | D105: =VLOOKUP(C105,'State Key'!$A$2:$B$210,2,False) -> Tamil Nadu | E105: 525 | F105: 0 | G105: 0 | H105: 0 | I105: 66.574 | J105: 0 | K105: 0 | L105: 66.574 | M105: 67.9 | N105: 19.37 | O105: 8.6 | P105: =SUM(F105:K105) -> 66.574
A106: April 2023 | B106: Southern | C106: TUTICORIN TPS | D106: =VLOOKUP(C106,'State Key'!$A$2:$B$210,2,False) -> Tamil Nadu | E106: 1050 | F106: 507.763 | G106: 0 | H106: 0 | I106: 0 | J106: 0 | K106: 0 | L106: 507.763 | M106: 550.903 | N106: 253.41 | O106: 13.8 | P106: =SUM(F106:K106) -> 507.763
A107: April 2023 | B107: Southern | C107: UDUPI TPP | D107: =VLOOKUP(C107,'State Key'!$A$2:$B$210,2,False) -> Karnataka | E107: 1200 | F107: 27.043 | G107: 0 | H107: 0 | I107: 215.436 | J107: 0 | K107: 0 | L107: 242.479 | M107: 165.9218 | N107: 124.5 | O107: 22.5 | P107: =SUM(F107:K107) -> 242.479
A108: April 2023 | B108: Southern | C108: VALLUR TPP | D108: =VLOOKUP(C108,'State Key'!$A$2:$B$210,2,False) -> Tamil Nadu | E108: 1500 | F108: 515.572 | G108: 0 | H108: 0 | I108: 73 | J108: 0 | K108: 0 | L108: 588.572 | M108: 683.697 | N108: 199.75 | O108: 8.8 | P108: =SUM(F108:K108) -> 588.572
A109: April 2023 | B109: Southern | C109: VIZAG TPP | D109: =VLOOKUP(C109,'State Key'!$A$2:$B$210,2,False) -> Andhra Pradesh | E109: 1040 | F109: 317.7124 | G109: 0 | H109: 0 | I109: 23.7352 | J109: 0 | K109: 0 | L109: 341.4476 | M109: 322.241 | N109: 79.8661 | O109: 7.4 | P109: =SUM(F109:K109) -> 341.4476
...

Sheet Comparison
A1: SOURCE: https://www.data.gov.in/resource/stateut-wise-details-domestic-receipt-and-consumption-coal-domestic-coal-based-plants-2014
A2: Sl. No. | B2: State | C2: 2023-24 - Total Consumption (Millions of Tonnes) | D2: 23-2024 total per original data (Millions of Tonnes)
A3: 1 | B3: Delhi | C3: 0 | D3: N/A
A4: 2 | B4: Haryana | C4: 19.3 | D4: =SUMIFS('Master Data'!M51:M1514,'Master Data'!D51:D1514, "Haryana")/1000 -> 14.752221
A5: 3 | B5: Punjab | C5: 21.1 | D5: =SUMIFS('Master Data'!M48:M1510,'Master Data'!D48:D1510, "Punjab")/1000 -> 16.14692
A6: 4 | B6: Rajasthan | C6: 33.6 | D6: =SUMIFS('Master Data'!M1:M1620,'Master Data'!D1:D1620, "Rajasthan")/1000 -> 25.101988
A7: 5 | B7: Uttar Pradesh | C7: 99.7 | D7: =SUMIFS('Master Data'!M2:M1621,'Master Data'!D2:D1621, "Uttar Pradesh")/1000 -> 75.905263
A8: 6 | B8: Chhattisgarh | C8: 116.2 | D8: =SUMIFS('Master Data'!M2:M1621,'Master Data'!D2:D1621, "Chhattisgarh")/1000 -> 86.675224
A9: 7 | B9: Gujarat | C9: 15.8 | D9: =SUMIFS('Master Data'!M2:M1621,'Master Data'!D2:D1621, "Gujarat")/1000 -> 28.714433
A10: 8 | B10: Madhya Pradesh | C10: 93.4 | D10: =SUMIFS('Master Data'!M2:M1621,'Master Data'!D2:D1621, "Madhya Pradesh")/1000 -> 69.673836
A11: 9 | B11: Maharashtra | C11: 90.8 | D11: =SUMIFS('Master Data'!M2:M1621,'Master Data'!D2:D1621, "Maharashtra")/1000 -> 69.746375
A12: 10 | B12: Andhra Pradesh | C12: 49.1 | D12: =SUMIFS('Master Data'!M2:M1621,'Master Data'!D2:D1621, "Andhra Pradesh")/1000 -> 37.45002
A13: 11 | B13: Karnataka | C13: 25.4 | D13: =SUMIFS('Master Data'!M2:M1621,'Master Data'!D2:D1621, "Karnataka")/1000 -> 21.589594
A14: 12 | B14: Tamil Nadu | C14: 31.7 | D14: =SUMIFS('Master Data'!M2:M1621,'Master Data'!D2:D1621, "Tamil Nadu")/1000 -> 30.249006
A15: 13 | B15: Telangana | C15: 36.9 | D15: =SUMIFS('Master Data'!M2:M1621,'Master Data'!D2:D1621, "Telangana")/1000 -> 26.999568
A16: 14 | B16: Bihar | C16: 40.9 | D16: =SUMIFS('Master Data'!M2:M1621,'Master Data'!D2:D1621, "Bihar")/1000 -> 30.291395 | F16: <-- Note that these are probably similar because the data we have starts at April
A17: 15 | B17: Jharkhand | C17: 23.2 | D17: =SUMIFS('Master Data'!M2:M1621,'Master Data'!D2:D1621, "Jharkhand")/1000 -> 17.111033
A18: 16 | B18: Odisha | C18: 48.2 | D18: =SUMIFS('Master Data'!M2:M1621,'Master Data'!D2:D1621, "Odisha")/1000 -> 35.643398
A19: 17 | B19: West Bengal | C19: 59.3 | D19: =SUMIFS('Master Data'!M2:M1621,'Master Data'!D2:D1621, "West Bengal")/1000 -> 45.003287
A20: 18 | B20: Assam | C20: 3.1 | D20: =SUMIFS('Master Data'!M2:M1621,'Master Data'!D2:D1621, "Assam")/1000 -> 0
A21: All State-DCB | B21: All State-DCB | C21: 807.8 | D21: =SUM(D4:D19) -> 631.05356

Sheet All-India Monthly Summary
A1: All-India Monthly Coal Summary — National Power Portal | Quantities in '000 Tonnes
A2: Period | B2: Year | C2: Month | D2: CIL ('000T) | E2: SCCL ('000T) | F2: Captive ('000T) | G2: E-Auction ('000T) | H2: Import ('000T) | I2: Others ('000T) | J2: Total Receipt ('000T) | K2: Total Consump. ('000T) | L2: Closing Stocks ('000T) | M2: Net Surplus / Deficit ('000T) | N2: CIL % | O2: Captive % | P2: E-Auction % | Q2: Import % | R2: Market Coal %
A3: April 2023 | B3: 2023 | C3: 4 | D3: 47851.967 | E3: 5268.2417 | F3: 8760.5665 | G3: 4782.9893 | H3: 491.68228 | I3: 2732.5134 | J3: 69887.96 | K3: 71026.193 | L3: 35725.162 | M3: -1138.2324 | N3: 0.6847 | O3: 0.1254 | P3: 0.0684 | Q3: 0.007 | R3: 0.0754
A4: May 2023 | B4: 2023 | C4: 5 | D4: 49103.869 | E4: 5426.1639 | F4: 8885.3179 | G4: 4650.0049 | H4: 482.1802 | I4: 3351.9844 | J4: 71899.521 | K4: 71243.334 | L4: 36487.692 | M4: 656.1866 | N4: 0.683 | O4: 0.1236 | P4: 0.0647 | Q4: 0.0067 | R4: 0.0714
A5: June 2023 | B5: 2023 | C5: 6 | D5: 47288.49 | E5: 5051.6076 | F5: 8155.5643 | G5: 4762.6782 | H5: 322.1407 | I5: 2827.9458 | J5: 68408.426 | K5: 69162.138 | L5: 35188.19 | M5: -753.71117 | N5: 0.6913 | O5: 0.1192 | P5: 0.0696 | Q5: 0.0047 | R5: 0.0743
A6: July 2023 | B6: 2023 | C6: 7 | D6: 46116.783 | E6: 4274.0076 | F6: 8805.5377 | G6: 3637.881 | H6: 409.888 | I6: 3133.9562 | J6: 66378.054 | K6: 66919.716 | L6: 34648.747 | M6: -541.6624 | N6: 0.6948 | O6: 0.1327 | P6: 0.0548 | Q6: 0.0062 | R6: 0.061
A7: August 2023 | B7: 2023 | C7: 8 | D7: 45524.159 | E7: 4781.4892 | F7: 7749.1787 | G7: 4333.6618 | H7: 585.0579 | I7: 2888.1454 | J7: 65861.692 | K7: 71111.808 | L7: 29245.847 | M7: -5250.1161 | N7: 0.6912 | O7: 0.1177 | P7: 0.0658 | Q7: 0.0089 | R7: 0.0747
A8: September 2023 | B8: 2023 | C8: 9 | D8: 44191.837 | E8: 4566.7886 | F8: 7533.0491 | G8: 5548.3841 | H8: 726.1646 | I8: 2577.3538 | J8: 65143.578 | K8: 71127.853 | L8: 23117.382 | M8: -5984.2758 | N8: 0.6784 | O8: 0.1156 | P8: 0.0852 | Q8: 0.0111 | R8: 0.0963
A9: October 2023 | B9: 2023 | C9: 10 | D9: 48633.892 | E9: 5265.1319 | F9: 7691.0334 | G9: 7496.7361 | H9: 599.51612 | I9: 3030.1161 | J9: 72716.426 | K9: 75425.37 | L9: 20494.64 | M9: -2708.9442 | N9: 0.6688 | O9: 0.1058 | P9: 0.1031 | Q9: 0.0082 | R9: 0.1113
A10: November 2023 | B10: 2023 | C10: 11 | D10: 49610.946 | E10: 5260.9252 | F10: 8702.9637 | G10: 5869.7428 | H10: 1012.3792 | I10: 2912.8522 | J10: 73369.809 | K10: 66913.17 | L10: 27170.399 | M10: 6456.6389 | N10: 0.6762 | O10: 0.1186 | P10: 0.08 | Q10: 0.0138 | R10: 0.0938
A11: December 2023 | B11: 2023 | C11: 12 | D11: 50765.02 | E11: 5404.1126 | F11: 9541.5802 | G11: 5419.2893 | H11: 1063.6023 | I11: 3214.3426 | J11: 75407.947 | K11: 67627.544 | L11: 35155.111 | M11: 7780.4036 | N11: 0.6732 | O11: 0.1265 | P11: 0.0719 | Q11: 0.0141 | R11: 0.086
A12: January 2024 | B12: 2024 | C12: 1 | D12: 51509.352 | E12: 6022.2334 | F12: 9088.2916 | G12: 3273.2056 | H12: 6122.2144 | I12: 1066.3276 | J12: 77081.625 | K12: 73226.061 | L12: 39230.535 | M12: 3855.5635 | N12: 0.6682 | O12: 0.1179 | P12: 0.0425 | Q12: 0.0794 | R12: 0.1219
A13: February 2024 | B13: 2024 | C13: 2 | D13: 49400.691 | E13: 5641.0567 | F13: 9494.6978 | G13: 2477.4971 | H13: 6274.5762 | I13: 1141.3805 | J13: 74429.899 | K13: 68574.193 | L13: 44292.15 | M13: 5855.7054 | N13: 0.6637 | O13: 0.1276 | P13: 0.0333 | Q13: 0.0843 | R13: 0.1176
A14: March 2024 | B14: 2024 | C14: 3 | D14: 52534.265 | E14: 6217.407 | F14: 10509.982 | G14: 3143.3423 | H14: 6671.6852 | I14: 1280.9857 | J14: 80357.667 | K14: 74215.743 | L14: 50234.454 | M14: 6141.9238 | N14: 0.6538 | O14: 0.1308 | P14: 0.0391 | Q14: 0.083 | R14: 0.1221
... A36: January 2026 | B36: 2026 | C36: 1 | D36: 50846.63 | E36: 4794.3018 | F36: 13612.056 | G36: 1784.4949 | H36: 3631.0411 | I36: 1527.3594 | J36: 76195.884 | K36: 73949.272 | L36: 55987.911 | M36: 2246.6119 | N36: 0.6673 | O36: 0.1786 | P36: 0.0234 | Q36: 0.0477 | R36: 0.0711
A37: GRAND TOTAL | D37: 1626089.8 | E37: 168436.98 | F37: 372766.67 | G37: 95091.327 | H37: 127806.5 | I37: 61349.907 | J37: 2451541.2 | K37: 2430782.5 | L37: 1437152.4

Sheet Regional Monthly Summary
A1: Regional Monthly Coal Summary — National Power Portal | Quantities in '000 Tonnes
A2: Period | B2: Region | C2: Plants (#) | D2: CIL ('000T) | E2: SCCL ('000T) | F2: Captive ('000T) | G2: E-Auction ('000T) | H2: Import ('000T) | I2: Others ('000T) | J2: Total Receipt ('000T) | K2: Total Consump. ('000T) | L2: Net Balance ('000T) | M2: Closing Stocks ('000T) | N2: E-Auction % | O2: Import % | P2: Market Coal %
A3: April 2023 | B3: Eastern | C3: 37 | D3: 9533.1893 | E3: 8.169 | F3: 4267.506 | G3: 264.47 | H3: 30.27 | I3: 345.054 | J3: 14448.658 | K3: 14602.435 | L3: -153.7767 | M3: 6011.992 | N3: 0.0183 | O3: 0.0021 | P3: 0.0204
A4: April 2023 | B4: Northern | C4: 37 | D4: 12988.579 | E4: 12.145 | F4: 1479.225 | G4: 451.9575 | H4: 0 | I4: 0.067 | J4: 14931.973 | K4: 14036.089 | L4: 895.88406 | M4: 10796.336 | N4: 0.0303 | O4: 0 | P4: 0.0303
A5: April 2023 | B5: Southern | C5: 33 | D5: 5617.4422 | E5: 4800.9507 | F5: 614.71371 | G5: 2059.4482 | H5: 0 | I5: 0 | J5: 13092.555 | K5: 13811.875 | L5: -719.32008 | M5: 4530.6525 | N5: 0.1573 | O5: 0 | P5: 0.1573
A6: April 2023 | B6: Western | C6: 72 | D6: 19712.757 | E6: 446.977 | F6: 2399.1218 | G6: 2007.1136 | H6: 461.41228 | I6: 2387.3924 | J6: 27414.774 | K6: 28575.794 | L6: -1161.0197 | M6: 14386.182 | N6: 0.0732 | O6: 0.0168 | P6: 0.09
A7: May 2023 | B7: Eastern | C7: 37 | D7: 10133.747 | E7: 16.23 | F7: 4028.5088 | G7: 270.896 | H7: 24.634 | I7: 510.812 | J7: 14984.828 | K7: 14532.03 | L7: 452.7978 | M7: 6443.335 | N7: 0.0181 | O7: 0.0016 | P7: 0.0197
A8: May 2023 | B8: Northern | C8: 37 | D8: 12723.789 | E8: 0 | F8: 1216.8322 | G8: 316.14913 | H8: 0.07 | I8: 0 | J8: 14256.84 | K8: 14176.066 | L8: 80.77449 | M8: 10858.887 | N8: 0.0222 | O8: 0 | P8: 0.0222
A9: May 2023 | B9: Southern | C9: 33 | D9: 5766.1524 | E9: 4938.2229 | F9: 895.33678 | G9: 2337.1228 | H9: 0 | I9: 11.72957 | J9: 13948.565 | K9: 13320.87 | L9: 627.69493 | M9: 5112.5621 | N9: 0.1676 | O9: 0 | P9: 0.1676
A10: May 2023 | B10: Western | C10: 72 | D10: 20480.181 | E10: 471.711 | F10: 2744.6401 | G10: 1725.837 | H10: 457.4762 | I10: 2829.4428 | J10: 28709.288 | K10: 29214.369 | L10: -505.08062 | M10: 14072.908 | N10: 0.0601 | O10: 0.0159 | P10: 0.076
A11: June 2023 | B11: Eastern | C11: 37 | D11: 9605.1061 | E11: 12.342 | F11: 3602.192 | G11: 147.9776 | H11: 6.152 | I11: 263.905 | J11: 13637.675 | K11: 13906.783 | L11: -269.10815 | M11: 6122.224 | N11: 0.0109 | O11: 0.0005 | P11: 0.0114
A12: June 2023 | B12: Northern | C12: 37 | D12: 12879.308 | E12: 0.27668 | F12: 963.57319 | G12: 250.6724 | H12: 0 | I12: 0 | J12: 14093.83 | K12: 14947.108 | L12: -853.27811 | M12: 9849.143 | N12: 0.0178 | O12: 0 | P12: 0.0178
A13: June 2023 | B13: Southern | C13: 33 | D13: 5502.8455 | E13: 4601.9889 | F13: 438.63323 | G13: 1984.8388 | H13: 0 | I13: 0 | J13: 12528.306 | K13: 12833.548 | L13: -305.24117 | M13: 4731.4367 | N13: 0.1584 | O13: 0 | P13: 0.1584
A14: June 2023 | B14: Western | C14: 72 | D14: 19301.231 | E14: 437 | F14: 3151.1659 | G14: 2379.1894 | H14: 315.9887 | I14: 2564.0408 | J14: 28148.615 | K14: 27474.699 | L14: 673.91626 | M14: 14485.386 | N14: 0.0845 | O14: 0.0112 | P14: 0.0957
... A138: January 2026 | B138: Western | C138: 69 | D138: 20678.156 | E138: 868.548 | F138: 4392.7956 | G138: 975.88515 | H138: 1854.966 | I138: 1158.1154 | J138: 29928.466 | K138: 29227.581 | L138: 700.88451 | M138: 21129.099 | N138: 0.0326 | O138: 0.062 | P138: 0.0946

Sheet Plant Summary
A1: Plant-Level Cumulative Summary — April 2023 to January 2026 | Quantities in '000 Tonnes (Cumulative)
A2: Plant / TPS Name | B2: Region | C2: State | D2: Coordinates | E2: Installed MW | F2: Periods (#) | G2: CIL (Cumul.) | H2: SCCL (Cumul.) | I2: Captive (Cumul.) | J2: E-Auction (Cumul.) | K2: Import (Cumul.) | L2: Others (Cumul.) | M2: Total Receipt (Cumul.) | N2: Total Consump. (Cumul.) | O2: Latest Stocks | P2: Avg Stock Cover (Days) | Q2: CIL % | R2: E-Auction % | S2: Market Coal %
A3: ◆ EASTERN REGION
A4: BANDEL TPS | B4: Eastern | C4: West Bengal | D4: 22.995705, 88.404090 | E4: 270 | F4: 34 | G4: 43.003 | H4: 0 | I4: 3730.524 | J4: 0 | K4: 0 | L4: 7.626 | M4: 3781.153 | N4: 3741.253 | O4: 58.1 | P4: 12.672727 | Q4: 0.0114 | R4: 0 | S4: 0
A5: BARAUNI TPS | B5: Eastern | C5: Bihar | D5: 25.391300, 86.023400 | E5: 710 | F5: 34 | G5: 826.68 | H5: 0 | I5: 5334.19 | J5: 0 | K5: 0 | L5: 510.13 | M5: 6671 | N5: 6520.431 | O5: 159.84 | P5: 24.175758 | Q5: 0.1239 | R5: 0 | S5: 0
A6: BARH STPS | B6: Eastern | C6: Bihar | D6: 25.469300, 85.745100 | E6: 2640 | F6: 34 | G6: 16095.488 | H6: 0 | I6: 14681.33 | J6: 282.294 | K6: 329.268 | L6: 525.46 | M6: 31913.84 | N6: 31410.729 | O6: 845.5 | P6: 19.115152 | Q6: 0.5043 | R6: 0.0088 | S6: 0.0191
A7: BOKARO TPS `A` EXP | B7: Eastern | C7: Jharkhand | D7: 23.782944, 85.883391 | E7: 500 | F7: 34 | G7: 5248.1177 | H7: 0 | I7: 283.85 | J7: 6.506 | K7: 6.631 | L7: 0 | M7: 5545.1047 | N7: 5491.491 | O7: 181.24 | P7: 35.08125 | Q7: 0.9464 | R7: 0.0012 | S7: 0.0024
A8: BUDGE BUDGE TPS | B8: Eastern | C8: West Bengal | D8: 22.468889, 88.139722 | E8: 750 | F8: 34 | G8: 3126.6589 | H8: 0 | I8: 3159.3007 | J8: 2359.9733 | K8: 0 | L8: 841.8804 | M8: 9487.8133 | N8: 9767.7858 | O8: 149.19 | P8: 17.236364 | Q8: 0.3295 | R8: 0.2487 | S8: 0.2487
A9: BUXAR TPP | B9: Eastern | C9: Bihar | D9: 25.509199, 83.892355 | E9: 660 | F9: 3 | G9: 378.59722 | H9: 0 | I9: 0 | J9: 0 | K9: 0 | L9: 0 | M9: 378.59722 | N9: 326.265 | O9: 79.68 | P9: 11.7 | Q9: 1 | R9: 0 | S9: 0
A10: CHANDRAPURA(DVC) TPS | B10: Eastern | C10: Jharkhand | D10: 23.738136, 86.127145 | E10: 500 | F10: 34 | G10: 4591.25 | H10: 0 | I10: 2146.655 | J10: 37.709 | K10: 25.718 | L10: 0 | M10: 6801.332 | N10: 6888.8019 | O10: 147.72 | P10: 26.609091 | Q10: 0.6751 | R10: 0.0055 | S10: 0.0093
A11: D.P.L. TPS | B11: Eastern | C11: West Bengal | D11: 23.521100, 87.302300 | E11: 550 | F11: 34 | G11: 4032.6282 | H11: 0 | I11: 1930.7633 | J11: 61.611 | K11: 0 | L11: 347.652 | M11: 6372.6545 | N11: 6291.7951 | O11: 52.17 | P11: 12.445455 | Q11: 0.6328 | R11: 0.0097 | S11: 0.0097
A12: DARLIPALI STPS | B12: Eastern | C12: Odisha | D12: 21.963554, 83.891870 | E12: 1600 | F12: 34 | G12: 789.03 | H12: 0 | I12: 23872.62 | J12: 0 | K12: 0 | L12: 0 | M12: 24661.65 | N12: 24557.844 | O12: 372.43 | P12: 20.657576 | Q12: 0.032 | R12: 0 | S12: 0
A13: DERANG TPP | B13: Eastern | C13: Odisha | D13: 21.123800, 84.984300 | E13: 1200 | F13: 34 | G13: 13276.821 | H13: 0 | I13: 0 | J13: 3702.522 | K13: 0 | L13: 1677.3193 | M13: 18656.662 | N13: 17800.161 | O13: 1316.05 | P13: 58.806061 | Q13: 0.7116 | R13: 0.1985 | S13: 0.1985
A14: DISHERGARH TPP | B14: Eastern | C14: West Bengal | D14: 23.690640, 86.827350 | E14: 12 | F14: 23 | G14: 98.594 | H14: 0 | I14: 0 | J14: 0 | K14: 0 | L14: 0 | M14: 98.594 | N14: 92.306 | O14: 8.1 | P14: 36.455556 | Q14: 1 | R14: 0 | S14: 0
A15: DURGAPUR STEEL TPS | B15: Eastern | C15: West Bengal | D15: 23.580000, 87.204300 | E15: 1000 | F15: 34 | G15: 11791.735 | H15: 44.834 | I15: 133.276 | J15: 133.328 | K15: 30.247 | L15: 38.604 | M15: 12172.024 | N15: 11997.777 | O15: 237.33 | P15: 21.018182 | Q15: 0.9688 | R15: 0.011 | S15: 0.0135
... A40: TENUGHAT TPS | B40: Eastern | C40: Jharkhand | D40: 23.757300, 85.893600 | E40: 420 | F40: 34 | G40: 5019.546 | H40: 0 | I40: 0 | J40: 0 | K40: 0 | L40: 0 | M40: 5019.546 | N40: 4637.255 | O40: 381.15 | P40: 33.630303 | Q40: 1 | R40: 0 | S40: 0
A41: TITAGARH TPS | B41: Eastern | C41: West Bengal | D41: 22.731944, 88.370556 | E41: 240 | F41: 25 | G41: 0 | H41: 0 | I41: 0 | J41: 0 | K41: 0 | L41: 0 | M41: 0 | N41: 0 | O41: 0 | P41: — | Q41: 0 | R41: 0 | S41: 0
A42: UTKAL TPP (IND BARATH) | B42: Eastern | C42: Odisha | D42: 21.657942, 83.919513 | E42: 350 | F42: 22 | G42: 600.2712 | H42: 0 | I42: 0 | J42: 0 | K42: 0 | L42: 0 | M42: 600.2712 | N42: 495.5478 | O42: 240.427 | P42: 79.566667 | Q42: 1 | R42: 0 | S42: 0
A43: VEDANTA TPP | B43: Eastern | C43: Odisha | D43: 21.814523, 84.039929 | E43: 600 | F43: 34 | G43: 6037.7633 | H43: 0 | I43: 0 | J43: 0 | K43: 0 | L43: 12.94 | M43: 6050.7033 | N43: 6082.4755 | O43: 102.96 | P43: 22.093548 | Q43: 0.9979 | R43: 0 | S43: 0
A44: ◆ NORTHERN REGION
A45: ANPARA C TPS | B45: Northern | C45: Uttar Pradesh | D45: 24.204112, 82.797685 | E45: 1200 | F45: 34 | G45: 14575.528 | H45: 0 | I45: 0 | J45: 0 | K45: 0 | L45: 0 | M45: 14575.528 | N45: 14787.402 | O45: 56.53 | P45: 13.187879 | Q45: 1 | R45: 0 | S45: 0
A46: ANPARA TPS | B46: Northern | C46: Uttar Pradesh | D46: 26.192778, 79.940278 | E46: 2630 | F46: 34 | G46: 34423.249 | H46: 0 | I46: 0 | J46: 0 | K46: 0 | L46: 0 | M46: 34423.249 | N46: 34488.04 | O46: 865.24 | P46: 19.50303 | Q46: 1 | R46: 0 | S46: 0
A47: BARKHERA TPS | B47: Northern | C47: Uttar Pradesh | D47: 28.474784, 79.804071 | E47: 90 | F47: 34 | G47: 823.642 | H47: 0 | I47: 0 | J47: 0 | K47: 0 | L47: 0 | M47: 823.642 | N47: 813.454 | O47: 46.27 | P47: 114.76364 | Q47: 1 | R47: 0 | S47: 0
A48: CHHABRA-I PH-1 TPP | B48: Northern | C48: Rajasthan | D48: 24.620920, 77.035439 | E48: 500 | F48: 34 | G48: 5019.4302 | H48: 0 | I48: 0 | J48: 1.94 | K48: 0 | L48: 0 | M48: 5021.3702 | N48: 6600.1669 | O48: 135.0604 | P48: 24 | Q48: 0.9996 | R48: 0.0004 | S48: 0.0004
A49: CHHABRA-I PH-2 TPP | B49: Northern | C49: Rajasthan | D49: 24.620920, 77.035439 | E49: 500 | F49: 34 | G49: 3492.8194 | H49: 0 | I49: 4203.2948 | J49: 1.94 | K49: 0 | L49: 0 | M49: 7698.0542 | N49: 6019.8669 | O49: 123.8386 | P49: 19.775758 | Q49: 0.4537 | R49: 0.0003 | S49: 0.0003
A50: CHHABRA-II TPP | B50: Northern | C50: Uttar Pradesh | D50: 25.214299, 81.650820 | E50: 1320 | F50: 34 | G50: 2813.7418 | H50: 363.65167 | I50: 9405.7362 | J50: 248.53419 | K50: 0 | L50: 0 | M50: 12831.664 | N50: 12506.622 | O50: 431.09 | P50: 24.015152 | Q50: 0.2193 | R50: 0.0194 | S50: 0.0194
A51: DADRI (NCTPP) | B51: Northern | C51: Uttar Pradesh | D51: 28.602951, 77.608163 | E51: 1820 | F51: 34 | G51: 14983.04 | H51: 12.24 | I51: 2756.03 | J51: 439.607 | K51: 625.75 | L51: 507.25 | M51: 19323.917 | N51: 19036.411 | O51: 296.05 | P51: 23.545455 | Q51: 0.7754 | R51: 0.0227 | S51: 0.0551
A52: GH TPS (LEH.MOH.) | B52: Northern | C52: Punjab | D52: 30.266600, 75.166100 | E52: 920 | F52: 34 | G52: 2172.4977 | H52: 0 | I52: 6836.7158 | J52: 0 | K52: 0 | L52: 6.35138 | M52: 9015.5649 | N52: 8889.733 | O52: 361.67 | P52: 36.666667 | Q52: 0.241 | R52: 0 | S52: 0
A53: GHATAMPUR TPP | B53: Northern | C53: Uttar Pradesh | D53: 26.170025, 80.169886 | E53: 660 | F53: 13 | G53: 2765.761 | H53: 0 | I53: 0 | J53: 4.001 | K53: 0 | L53: 0 | M53: 2769.762 | N53: 2558.234 | O53: 181.08 | P53: 14.145455 | Q53: 0.9986 | R53: 0.0014 | S53: 0.0014
A54: GOINDWAL SAHIB TPP | B54: Northern | C54: Punjab | D54: 31.384100, 75.146400 | E54: 540 | F54: 34 | G54: 1866.9885 | H54: 0 | I54: 3134.9508 | J54: 0 | K54: 0 | L54: 0 | M54: 5001.9393 | N54: 4869.4105 | O54: 157.41 | P54: 28.99697 | Q54: 0.3733 | R54: 0 | S54: 0
A55: HARDUAGANJ TPS | B55: Northern | C55: Uttar Pradesh | D55: 28.017861, 78.129366 | E55: 1265 | F55: 34 | G55: 11495.694 | H55: 0 | I55: 0 | J55: 0 | K55: 0 | L55: 0 | M55: 11495.694 | N55: 11336.54 | O55: 483.95 | P55: 46.284848 | Q55: 1 | R55: 0 | S55: 0
A56: INDIRA GANDHI STPP | B56: Northern | C56: Haryana | D56: 28.485091, 76.373160 | E56: 1500 | F56: 34 | G56: 15641.17 | H56: 104.31868 | I56: 0 | J56: 352.0228 | K56: 83.842 | L56: 4.98059 | M56: 16186.334 | N56: 15938.352 | O56: 367.3 | P56: 39.039394 | Q56: 0.9663 | R56: 0.0217 | S56: 0.0269
... A68: OBRA TPS | B68: Northern | C68: Uttar Pradesh | D68: 24.445478, 82.980707 | E68: 1000 | F68: 34 | G68: 16873.304 | H68: 0 | I68: 0 | J68: 0 | K68: 0 | L68: 0 | M68: 16873.304 | N68: 16159.16 | O68: 674.05 | P68: 16.142424 | Q68: 1 | R68: 0 | S68: 0
A69: OBRA-C STPP | B69: Northern | C69: Uttar Pradesh | D69: 24.445478, 82.980707 | E69: 660 | F69: 1 | G69: 0 | H69: 0 | I69: 0 | J69: 0 | K69: 0 | L69: 0 | M69: 0 | N69: 0 | O69: 0 | P69: — | Q69: 0 | R69: 0 | S69: 0
A70: PANIPAT TPS | B70: Northern | C70: Haryana | D70: 29.398300, 76.875450 | E70: 710 | F70: 34 | G70: 8000.818 | H70: 0 | I70: 0 | J70: 7.898 | K70: 0 | L70: 20.064 | M70: 8028.78 | N70: 7976.47 | O70: 440.401 | P70: 50.793939 | Q70: 0.9965 | R70: 0.001 | S70: 0.001
A71: PANKI TPS EXT | B71: Northern | C71: Uttar Pradesh | D71: 26.476064, 80.241920 | E71: 660 | F71: 11 | G71: 1296.1847 | H71: 0 | I71: 0 | J71: 0 | K71: 0 | L71: 0 | M71: 1296.1847 | N71: 1174.7611 | O71: 101 | P71: 59.4 | Q71: 1 | R71: 0 | S71: 0
A72: PARICHHA TPS | B72: Northern | C72: Uttar Pradesh | D72: 25.513571, 78.757918 | E72: 1140 | F72: 34 | G72: 11126.191 | H72: 0 | I72: 0 | J72: 0 | K72: 4.145 | L72: 0 | M72: 11130.336 | N72: 11084.152 | O72: 161.257 | P72: 21.639394 | Q72: 0.9996 | R72: 0 | S72: 0.0004
A73: PRAYAGRAJ TPP | B73: Northern | C73: Uttar Pradesh | D73: 25.196345, 81.658534 | E73: 1980 | F73: 34 | G73: 21787.912 | H73: 0 | I73: 0 | J73: 0 | K73: 0 | L73: 0 | M73: 21787.912 | N73: 21690.77 | O73: 607.11 | P73: 24.930303 | Q73: 1 | R73: 0 | S73: 0
A74: RAJIV GANDHI TPS | B74: Northern | C74: Haryana | D74: 29.347597, 75.857981 | E74: 1200 | F74: 34 | G74: 10071.999 | H74: 0 | I74: 0 | J74: 0 | K74: 0 | L74: 0 | M74: 10071.999 | N74: 9894.167 | O74: 645.859 | P74: 53.409375 | Q74: 1 | R74: 0 | S74: 0
A75: RAJPURA TPP | B75: Northern | C75: Punjab | D75: 30.558963, 76.577593 | E75: 1400 | F75: 34 | G75: 15957.385 | H75: 0 | I75: 0 | J75: 38.63383 | K75: 0 | L75: 0 | M75: 15996.019 | N75: 16036.128 | O75: 392.78 | P75: 22.827273 | Q75: 0.9976 | R75: 0.0024 | S75: 0.0024
...

Sheet Variables
A1: Column | B1: Name
A3: Source of coals
A4: CIL | B4: Coal India Limited
A5: E-Auction | B5: Electronic auction | C5: Coal purchased through CIL's spot auction platform at market-discovered prices, typically 20–50% premium over FSA price. This is the most direct proxy for market-based coal procurement and the primary ETS-relevant variable in this dataset. Plants bid when FSA coal is insufficient. High E-Auction % = high price exposure. Volume correlates inversely with CIL supply adequacy.
A6: SCCL | B6: Singareni Collieries Company Limited | C6: A Telangana state PSU, the only major coal producer outside CIL. Primarily serves Southern and Western region plants (Andhra Pradesh, Telangana, Maharashtra). Plants with SCCL linkage are partly insulated from CIL supply shocks. Zero for Northern plants.
A7: Captive | C7: Coal from captive mines owned by the plant/parent company. These are blocks allocated directly to a power company — they mine their own coal. Examples: Adani Power (Parsa East), JSW, Vedanta. Captive supply is cost-efficient and supply-secure, making these plants largely ETS-independent. High captive % = low ETS vulnerability.
A8: Import | C8: Internationally imported coal, primarily from Indonesia, Australia, South Africa. Mostly used by coastal plants (Western coast: Mundra, Udupi; Southern: Ennore, Tuticorin). Priced in USD, highly volatile (exposed to global thermal coal prices). Import % typically rises when domestic E-Auction supply is tight. The 2023 period shows 7–9% import share — significantly higher than 2025 (4–5%), suggesting import substitution trend.

Sheet State Key
A1: Plant | B1: State | C1: Coordinates | D1: Latitude | E1: Longitude | F1: PM2.5 | G1: SO2
A2: {=UNIQUE('Master Data'!C4:C1000)} -> BAKRESWAR TPS | B2: West Bengal | C2: 23.829202829326025, 87.45166573824892 | D2: =VALUE(LEFT(C2, FIND(",", C2)-1)) -> 23.829203 | E2: =VALUE(TRIM(RIGHT(C2, LEN(C2)-FIND(",", C2)))) -> 87.451666 | F2: 5
A3: BANDEL TPS | B3: West Bengal | C3: 22.993459490018857, 88.40439285295527 | D3: =VALUE(LEFT(C3, FIND(",", C3)-1)) -> 22.993459 | E3: =VALUE(TRIM(RIGHT(C3, LEN(C3)-FIND(",", C3)))) -> 88.404393 | F3: 4
A4: BARAUNI TPS | B4: Bihar | C4: 25.400946710936868, 86.02202288002738 | D4: =VALUE(LEFT(C4, FIND(",", C4)-1)) -> 25.400947 | E4: =VALUE(TRIM(RIGHT(C4, LEN(C4)-FIND(",", C4)))) -> 86.022023 | F4: 3
A5: BARH STPS | B5: Bihar | C5: 25.488273732252495, 85.73691719537453 | D5: =VALUE(LEFT(C5, FIND(",", C5)-1)) -> 25.488274 | E5: =VALUE(TRIM(RIGHT(C5, LEN(C5)-FIND(",", C5)))) -> 85.736917 | F5: 2
A6: BOKARO TPS `A` EXP | B6: Jharkhand | C6: 23.786577398434446, 85.8794069559405 | D6: =VALUE(LEFT(C6, FIND(",", C6)-1)) -> 23.786577 | E6: =VALUE(TRIM(RIGHT(C6, LEN(C6)-FIND(",", C6)))) -> 85.879407 | F6: 1
A7: BUDGE BUDGE TPS | B7: West Bengal | C7: 22.466311214732713, 88.14007352224957 | D7: =VALUE(LEFT(C7, FIND(",", C7)-1)) -> 22.466311 | E7: =VALUE(TRIM(RIGHT(C7, LEN(C7)-FIND(",", C7)))) -> 88.140074 | F7: 5
A8: CHANDRAPURA(DVC) TPS | B8: Jharkhand | C8: 23.741948699750445, 86.12007382599734 | D8: =VALUE(LEFT(C8, FIND(",", C8)-1)) -> 23.741949 | E8: =VALUE(TRIM(RIGHT(C8, LEN(C8)-FIND(",", C8)))) -> 86.120074 | F8: 1
A9: D.P.L. TPS | B9: West Bengal | C9: 23.51989102640012, 87.30520887262757 | D9: =VALUE(LEFT(C9, FIND(",", C9)-1)) -> 23.519891 | E9: =VALUE(TRIM(RIGHT(C9, LEN(C9)-FIND(",", C9)))) -> 87.305209 | F9: 4
A10: DARLIPALI STPS | B10: Odisha | C10: 21.964189710299596, 83.89143277353463 | D10: =VALUE(LEFT(C10, FIND(",", C10)-1)) -> 21.96419 | E10: =VALUE(TRIM(RIGHT(C10, LEN(C10)-FIND(",", C10)))) -> 83.891433 | F10: 3.5
A11: DERANG TPP | B11: Odisha | C11: 21.126302666290904, 84.98623252220528
A12: DISHERGARH TPP | B12: West Bengal | C12: 23.690972065872916, 86.85381317264695
A13: DURGAPUR STEEL TPS | B13: West Bengal | C13: 23.581299668758863, 87.2076936855152
A14: FARAKKA STPS | B14: West Bengal | C14: 24.77354926398749, 87.89703503767562
A15: HALDIA TPP | B15: West Bengal | C15: 22.10312246232122, 88.17793313572948
A16: HIRANMAYE TPP | B16: West Bengal | C16: 22.077275436945826, 88.100879097907
A17: IB VALLEY TPS | B17: Odisha | C17: 21.69162375315987, 83.86242546455178
A18: JOJOBERA TPS | B18: Jharkhand | C18: 22.755489992042115, 86.24727329527514
A19: KAHALGAON TPS | B19: Bihar | C19: 25.237635101140896, 87.26740628372444
A20: KAMALANGA TPS | B20: Odisha | C20: 20.871033494494014, 85.26699099990599
A21: KODARMA TPP | B21: Jharkhand | C21: 24.395672373951346, 85.55814150343213
A22: KOLAGHAT TPS | B22: West Bengal | C22: 22.416006952004224, 87.87078673944328
... A53: KOTA TPS | B53: Rajasthan | C53: 25.173524724796458, 75.81756147513704
A54: KUNDARKI TPS | B54: Uttar Pradesh
A55: LALITPUR TPS | B55: Uttar Pradesh
A56: MAHATMA GANDHI TPS | B56: Haryana
A57: MAQSOODPUR TPS | B57: Uttar Pradesh
A58: MEJA STPP | B58: Uttar Pradesh
A59: OBRA TPS | B59: Uttar Pradesh
A60: PANIPAT TPS | B60: Haryana
A61: PARICHHA TPS | B61: Uttar Pradesh
A62: PRAYAGRAJ TPP | B62: Uttar Pradesh
A63: RAJIV GANDHI TPS | B63: Haryana
A64: RAJPURA TPP | B64: Punjab
A65: RIHAND STPS | B65: Uttar Pradesh
... A192: OPG Power Generation Private Limited | B192: Tamil Nadu
A193: ADANI POWER | B193: Karnataka | C193: ?
A194: LIMITED UDUPI TPP | B194: Karnataka
A195: Maadurga Thermal Power Company Ltd. | B195: Odisha
A196: GHATAMPUR TPP | B196: Uttar Pradesh
...
